Workbook

Sheet Data Dashboard
B2: Country | C2: AFGHANISTAN | D2: Please select country here
B4: Country Context | E4: Standard assumptions of costing model | H4: Summary of Results
B5: Income Group | C5: =VLOOKUP($C$2, 'LIC and MIC'!$A$2:$AH$73, 4, FALSE) -> LOW INCOME | E5: Number of years of education | H5: Number of refugee children to be enrolled
B6: Lending Category | C6: =VLOOKUP($C$2, 'LIC and MIC'!$A$2:$AH$73, 12, FALSE) -> IDA | E6: Pre-primary | F6: 1 | H6: Pre-primary | I6: =IF(SUM(F6:F7)=7, (F6/7*C14*F23), (F6/SUM($F$6:$F$9)*C16)) -> 1758.0314
E7: Primary | F7: 6 | H7: Primary | I7: =IF(SUM(F6:F7)=7, (F7/7*C14*F24), (F7/SUM(F6:F9)*C16)) -> 10548.189
B8: Refugee, asylum seeker and VDA population (end 2022) | E8: Lower Secondary | F8: 3 | H8: Lower Secondary | I8: =IF(SUM(F8:F9)=6, (F8/6*C15*F25), (F8/SUM($F$6:$F$9)*C16)) -> 3374.0432
B9: Refugees | C9: =VLOOKUP($C$2, 'LIC and MIC'!$A$2:$AH$73, 5, FALSE) -> 52159 | E9: Upper Secondary | F9: 3 | H9: Upper Secondary | I9: =IF(SUM(F8:F9)=6, (F9/6*C15*F26), (F9/SUM(F6:F9)*C16)) -> 3374.0432
B10: Asylum seekers | C10: =VLOOKUP($C$2, 'LIC and MIC'!$A$2:$AH$73, 6, FALSE) -> 218 | H10: Total | I10: =SUM(I6:I9) -> 19054.306
B11: Venezuelans displaced abroad | C11: =VLOOKUP($C$2, 'LIC and MIC'!$A$2:$AH$73, 7, FALSE) -> 0 | E11: Refugee Coefficients
B12: Total refugee population | C12: =SUM(C9:C11) -> 52377 | E12: Pre-primary | F12: 0.2 | H12: Refugee Education Costs Per Capita (US$)
E13: Primary | F13: 0.2 | H13: Pre-primary | I13: =(1+F12+F15)*C32 -> 109.36102
B14: Refugees aged 5-11 years | C14: =VLOOKUP($C$2, 'LIC and MIC'!$A$2:$AH$73, 14, FALSE) -> 12306.22 | E14: Secondary | F14: 0.35 | H14: Primary | I14: =(1+F13)*C32 -> 87.488818
B15: Refugees aged 12-17 years | C15: =VLOOKUP($C$2, 'LIC and MIC'!$A$2:$AH$73, 15, FALSE) -> 6748.0864 | E15: ECCE strengthening | F15: 0.3 | H15: Secondary | I15: =(1+F14)*C33 -> 107.34066
B16: Total school-aged refugee children | C16: =SUM(C14:C15) -> 19054.306
E17: Refugee Gross Enrollment Ratio | H17: Annual Cost of Inclusive Refugee Education (US$)
B18: Education Outcomes and Targets | E18: Pre-primary | F18: =VLOOKUP($C$2, Targets!$B$4:$AK$75, 16, FALSE) -> - | H18: Pre-primary | I18: =I6*I13 -> 192260.11
B19: Host Country Gross Enrollment Ratio (latest available year) | E19: Primary | F19: =VLOOKUP($C$2, Targets!$B$4:$AK$75, 17, FALSE) -> - | H19: Primary | I19: =I7*I14 -> 922848.55
B20: Pre-primary | C20: =VLOOKUP($C$2, Targets!$B$4:$AK$75, 12, FALSE)/100 -> 0.2014646 | E20: Secondary | F20: =VLOOKUP($C$2, Targets!$B$4:$AK$75, 18, FALSE) -> - | H20: Lower Secondary | I20: =I8*I15 -> 362172.01
B21: Primary | C21: =VLOOKUP($C$2, Targets!$B$4:$AK$75, 13, FALSE)/100 -> 1.1001 | H21: Upper Secondary | I21: =I9*I15 -> 362172.01
B22: Lower Secondary | C22: =VLOOKUP($C$2, Targets!$B$4:$AK$75, 14, FALSE)/100 -> 0.7238 | E22: Targets for Refugee Enrollment | H22: Total | I22: =SUM(I18:I21) -> 1839452.7
B23: Upper Secondary | C23: =VLOOKUP($C$2, Targets!$B$4:$AK$75, 15, FALSE)/100 -> 0.4204 | E23: Pre-primary | F23: 1
E24: Primary | F24: 1
B25: SDG National Benchmarks for Enrollment (2030) | E25: Lower Secondary | F25: 1
B26: Pre-primary | C26: =VLOOKUP($C$2, Targets!$B$4:$AK$75, 19, FALSE)/100 -> 0.69120705 | E26: Upper Secondary | F26: 1
B27: Primary | C27: =VLOOKUP($C$2, Targets!$B$4:$AK$75, 20, FALSE)/100 -> 0.81623322
B28: Lower Secondary | C28: =VLOOKUP($C$2, Targets!$B$4:$AK$75, 21, FALSE)/100 -> 0.81262644
B29: Upper Secondary | C29: =VLOOKUP($C$2, Targets!$B$4:$AK$75, 22, FALSE)/100 -> 0.68627749
B31: Public Expenditure on Education Per Capita (US$)
B32: Primary | C32: =VLOOKUP($C$2, 'LIC and MIC'!$A$2:$AH$73, 21, FALSE) -> 72.907348
B33: Secondary | C33: =VLOOKUP($C$2, 'LIC and MIC'!$A$2:$AH$73, 22, FALSE) -> 79.511597

Sheet LIC and MIC
A1: country | B1: code | C1: region | D1: incomegroup | E1: refugee | F1: asylum | G1: vda | H1: tot_pop | I1: age_coverage_ref | J1: pop_share_prm_ref | K1: pop_share_sec_ref | L1: lendingcategory | M1: pop_share_estimated | N1: pop_prm | O1: pop_sec | P1: pop_school_age | Q1: kg_enrol_2022 | R1: prm_enrol_2022 | S1: sec_enrol_2022 | T1: kg_host_cost_2022 | U1: prm_host_cost_2022 | V1: sec_host_cost_2022 | W1: kg_ref_cost_2022 | X1: prm_ref_cost_2022 | Y1: sec_ref_cost_2022 | Z1: kg_ref_cost_total | AA1: prm_ref_cost_total | AB1: sec_ref_cost_total | AC1: total_annual_cost | AD1: pub_edu_exp_gdppercent | AE1: GDP 2020 current US$ | AF1: public_edu_exp | AG1: ref_cost_pub_exp_ratio
A2: AFGHANISTAN | B2: AFG | C2: SOUTH ASIA | D2: LOW INCOME | E2: 52159 | F2: 218 | G2: 0 | H2: 52377 | I2: 1 | J2: 0.23495466 | K2: 0.12883683 | L2: IDA | M2: 0 | N2: 12306.22 | O2: 6748.0864 | P2: 19054.307 | Q2: 1758.0314 | R2: 10548.189 | S2: 6748.0864 | T2: =U2*1.3 -> 94.779552 | U2: 72.907348 | V2: 79.511597 | W2: =T2*1.2 -> 113.73546 | X2: 87.488818 | Y2: 107.34066 | Z2: =W2*Q2 -> 199950.52 | AA2: =X2*R2 -> 922848.58 | AB2: =Y2*S2 -> 724344.02 | AC2: =SUM(Z2:AB2) -> 1847143.1 | AD2: =VLOOKUP(A2,[1]Ark1!$A$3:$B$220, 2, FALSE) -> 3.0348 | AE2: =VLOOKUP(B2,[2]Data!$B$5:$BM$270, 64, FALSE) -> 2.0143452e+10 | AF2: =AD2/100*AE2 -> 6.1131347e+08 | AG2: =AC2/AF2*100 -> 0.30215973 | AH2: =IF(AG2<1, 1, 0) -> 1
A3: ALGERIA | B3: DZA | C3: MIDDLE EAST & NORTH AFRICA | D3: LOWER MIDDLE INCOME | E3: 99107 | F3: 3646 | G3: 0 | H3: 102753 | I3: 0.09 | J3: 0.18 | K3: 0.13 | L3: IBRD | M3: 1 | N3: 18495.54 | O3: 13357.89 | P3: 31853.43 | Q3: 2642.22 | R3: 15853.32 | S3: 13357.89 | T3: =U3*1.3 -> 638.95 | U3: 491.5 | V3: 765.03 | W3: =T3*1.2 -> 766.74 | X3: 589.8 | Y3: 1032.7905 | Z3: =W3*Q3 -> 2025895.8 | AA3: =X3*R3 -> 9350288.1 | AB3: =Y3*S3 -> 13795902 | AC3: =SUM(Z3:AB3) -> 25172086 | AD3: =VLOOKUP(A3,[1]Ark1!$A$3:$B$220, 2, FALSE) -> 6.288 | AE3: =VLOOKUP(B3,[2]Data!$B$5:$BM$270, 64, FALSE) -> 1.4574372e+11 | AF3: =AD3/100*AE3 -> 9.1643653e+09 | AG3: =AC3/AF3*100 -> 0.27467353 | AH3: =IF(AG3<1, 1, 0) -> 1
A4: ANGOLA | B4: AGO | C4: SUB-SAHARAN AFRICA | D4: LOWER MIDDLE INCOME | E4: 25514 | F4: 30268 | G4: 0 | H4: 55782 | I4: 0.36 | J4: 0.25567077 | K4: 0.15046446 | L4: IBRD | M4: 0 | N4: 14261.827 | O4: 8393.2087 | P4: 22655.036 | Q4: 2037.4039 | R4: 12224.423 | S4: 8393.2087 | T4: =U4*1.3 -> 185.58799 | U4: 142.75999 | V4: 229.91252 | W4: =T4*1.2 -> 222.70559 | X4: 171.31199 | Y4: 310.3819 | Z4: =W4*Q4 -> 453741.23 | AA4: =X4*R4 -> 2094190.2 | AB4: =Y4*S4 -> 2605100 | AC4: =SUM(Z4:AB4) -> 5153031.5 | AD4: =VLOOKUP(A4,[1]Ark1!$A$3:$B$220, 2, FALSE) -> 2.4152 | AE4: =VLOOKUP(B4,[2]Data!$B$5:$BM$270, 64, FALSE) -> 5.0241368e+10 | AF4: =AD4/100*AE4 -> 1.2134295e+09 | AG4: =AC4/AF4*100 -> 0.42466673 | AH4: =IF(AG4<1, 1, 0) -> 1
A5: ARGENTINA | B5: ARG | C5: LATIN AMERICA & CARIBBEAN | D5: UPPER MIDDLE INCOME | E5: 4094 | F5: 11100 | G5: 165174 | H5: 180368 | I5: 0.84 | J5: 0.01538837 | K5: 0.03737176 | L5: IBRD | M5: 0 | N5: 2775.5701 | O5: 6740.6702 | P5: 9516.2404 | Q5: 396.51001 | R5: 2379.0601 | S5: 6740.6702 | T5: =U5*1.3 -> 2358.3608 | U5: 1814.1237 | V5: 2156.6621 | W5: =T5*1.2 -> 2830.0329 | X5: 2176.9484 | Y5: 2911.4939 | Z5: =W5*Q5 -> 1122136.4 | AA5: =X5*R5 -> 5179091.1 | AB5: =Y5*S5 -> 19625420 | AC5: =SUM(Z5:AB5) -> 25926648 | AD5: =VLOOKUP(A5,[1]Ark1!$A$3:$B$220, 2, FALSE) -> 5.098 | AE5: =VLOOKUP(B5,[2]Data!$B$5:$BM$270, 64, FALSE) -> 3.8554041e+11 | AF5: =AD5/100*AE5 -> 1.965485e+10 | AG5: =AC5/AF5*100 -> 0.13190967 | AH5: =IF(AG5<1, 1, 0) -> 1
A6: ARMENIA | B6: ARM | C6: EUROPE & CENTRAL ASIA | D6: UPPER MIDDLE INCOME | E6: 34634 | F6: 580 | G6: 0 | H6: 35214 | I6: 0.06 | J6: 0.18 | K6: 0.13 | L6: IBRD | M6: 1 | N6: 6338.52 | O6: 4577.82 | P6: 10916.34 | Q6: 905.50286 | R6: 5433.0171 | S6: 4577.82 | T6: =U6*1.3 -> 907.63031 | U6: 698.17716 | V6: 686.48668 | W6: =T6*1.2 -> 1089.1564 | X6: 837.81259 | Y6: 926.75701 | Z6: =W6*Q6 -> 986234.21 | AA6: =X6*R6 -> 4551850.1 | AB6: =Y6*S6 -> 4242526.8 | AC6: =SUM(Z6:AB6) -> 9780611.2 | AD6: =VLOOKUP(A6,[1]Ark1!$A$3:$B$220, 2, FALSE) -> 2.7057 | AE6: =VLOOKUP(B6,[2]Data!$B$5:$BM$270, 64, FALSE) -> 1.2641699e+10 | AF6: =AD6/100*AE6 -> 3.4204644e+08 | AG6: =AC6/AF6*100 -> 2.8594395 | AH6: =IF(AG6<1, 1, 0) -> 0
A7: BANGLADESH | B7: BGD | C7: SOUTH ASIA | D7: LOWER MIDDLE INCOME | E7: 952384 | F7: 24 | G7: 0 | H7: 952408 | I7: 1 | J7: 0.22271794 | K7: 0.1406355 | L7: IDA | M7: 0 | N7: 212118.35 | O7: 133942.38 | P7: 346060.72 | Q7: 30302.621 | R7: 181815.72 | S7: 133942.38 | T7: =U7*1.3 -> 200.25525 | U7: 154.0425 | V7: 147.24635 | W7: =T7*1.2 -> 240.3063 | X7: 184.851 | Y7: 198.78258 | Z7: =W7*Q7 -> 7281910.7 | AA7: =X7*R7 -> 33608817 | AB7: =Y7*S7 -> 26625411 | AC7: =SUM(Z7:AB7) -> 67516139 | AD7: =VLOOKUP(A7,[1]Ark1!$A$3:$B$220, 2, FALSE) -> 1.2892 | AE7: =VLOOKUP(B7,[2]Data!$B$5:$BM$270, 64, FALSE) -> 3.739022e+11 | AF7: =AD7/100*AE7 -> 4.8203471e+09 | AG7: =AC7/AF7*100 -> 1.4006489 | AH7: =IF(AG7<1, 1, 0) -> 0
A8: BELARUS | B8: BLR | C8: EUROPE & CENTRAL ASIA | D8: UPPER MIDDLE INCOME | E8: 19715 | F8: 639 | G8: 0 | H8: 20354 | I8: 0.16 | J8: 0.18 | K8: 0.13 | L8: IBRD | M8: 1 | N8: 3663.72 | O8: 2646.02 | P8: 6309.74 | Q8: 523.38857 | R8: 3140.3314 | S8: 2646.02 | T8: =U8*1.3 -> 1551.7826 | U8: 1193.6789 | V8: 2485.6063 | W8: =T8*1.2 -> 1862.1391 | X8: 1432.4147 | Y8: 3355.5685 | Z8: =W8*Q8 -> 974622.31 | AA8: =X8*R8 -> 4498256.8 | AB8: =Y8*S8 -> 8878901.2 | AC8: =SUM(Z8:AB8) -> 14351780 | AD8: =VLOOKUP(A8,[1]Ark1!$A$3:$B$220, 2, FALSE) -> 4.9524 | AE8: =VLOOKUP(B8,[2]Data!$B$5:$BM$270, 64, FALSE) -> 6.1371755e+10 | AF8: =AD8/100*AE8 -> 3.0393748e+09 | AG8: =AC8/AF8*100 -> 0.47219515 | AH8: =IF(AG8<1, 1, 0) -> 1
A9: BOLIVIA (PLURINATIONAL STATE OF) | B9: BOL | C9: LATIN AMERICA & CARIBBEAN | D9: LOWER MIDDLE INCOME | E9: 1116 | F9: 61 | G9: 13531 | H9: 14708 | J9: 0.18 | K9: 0.13 | L9: IBRD | M9: 1 | N9: 2647.44 | O9: 1912.04 | P9: 4559.48 | Q9: 378.20571 | R9: 2269.2343 | S9: 1912.04 | T9: =U9*1.3 -> 1442.6256 | U9: 1109.712 | V9: 888.21072 | W9: =T9*1.2 -> 1731.1507 | X9: 1331.6544 | Y9: 1199.0845 | Z9: =W9*Q9 -> 654731.1 | AA9: =X9*R9 -> 3021835.9 | AB9: =Y9*S9 -> 2292697.5 | AC9: =SUM(Z9:AB9) -> 5969264.5 | AD9: 8.9572 | AE9: =VLOOKUP(B9,[2]Data!$B$5:$BM$270, 64, FALSE) -> 3.6629844e+10 | AF9: =AD9/100*AE9 -> 3.2810084e+09 | AG9: =AC9/AF9*100 -> 0.18193384 | AH9: =IF(AG9<1, 1, 0) -> 1
A10: BRAZIL | B10: BRA | C10: LATIN AMERICA & CARIBBEAN | D10: UPPER MIDDLE INCOME | E10: 67522 | F10: 206764 | G10: 264040 | H10: 538326 | J10: 0.18 | K10: 0.13 | L10: IBRD | M10: 1 | N10: 96898.68 | O10: 69982.38 | P10: 166881.06 | Q10: 13842.669 | R10: 83056.011 | S10: 69982.38 | T10: =U10*1.3 -> 2569.3478 | U10: 1976.4214 | V10: 2034.023 | W10: =T10*1.2 -> 3083.2174 | X10: 2371.7057 | Y10: 2745.931 | Z10: =W10*Q10 -> 42679958 | AA10: =X10*R10 -> 1.9698441e+08 | AB10: =Y10*S10 -> 1.9216679e+08 | AC10: =SUM(Z10:AB10) -> 4.3183116e+08 | AD10: =VLOOKUP(A10,[1]Ark1!$A$3:$B$220, 2, FALSE) -> 5.7744 | AE10: =VLOOKUP(B10,[2]Data!$B$5:$BM$270, 64, FALSE) -> 1.4761073e+12 | AF10: =AD10/100*AE10 -> 8.5236339e+10 | AG10: =AC10/AF10*100 -> 0.506628 | AH10: =IF(AG10<1, 1, 0) -> 1
A11: BULGARIA | B11: BGR | C11: EUROPE & CENTRAL ASIA | D11: UPPER MIDDLE INCOME | E11: 176297 | F11: 11165 | G11: 0 | H11: 187462 | J11: 0.18 | K11: 0.13 | L11: IBRD | M11: 1 | N11: 33743.16 | O11: 24370.06 | P11: 58113.22 | Q11: 4820.4514 | R11: 28922.709 | S11: 24370.06 | T11: =U11*1.3 -> 3450.0144 | U11: 2653.8572 | V11: 2873.1552 | W11: =T11*1.2 -> 4140.0173 | X11: 3184.6287 | Y11: 3878.7596 | Z11: =W11*Q11 -> 19956752 | AA11: =X11*R11 -> 92108088 | AB11: =Y11*S11 -> 94525604 | AC11: =SUM(Z11:AB11) -> 2.0659044e+08 | AD11: =VLOOKUP(A11,[1]Ark1!$A$3:$B$220, 2, FALSE) -> 4.3895 | AE11: =VLOOKUP(B11,[2]Data!$B$5:$BM$270, 64, FALSE) -> 7.0404359e+10 | AF11: =AD11/100*AE11 -> 3.0903993e+09 | AG11: =AC11/AF11*100 -> 6.6849109 | AH11: =IF(AG11<1, 1, 0) -> 0
A12: BURKINA FASO | B12: BFA | C12: SUB-SAHARAN AFRICA | D12: LOW INCOME | E12: 34375 | F12: 551 | G12: 0 | H12: 34926 | I12: 1 | J12: 0.28619636 | K12: 0.14955636 | L12: IDA | M12: 0 | N12: 9995.6942 | O12: 5223.4056 | P12: 15219.1 | Q12: 1427.9563 | R12: 8567.7379 | S12: 5223.4056 | T12: =U12*1.3 -> 215.93639 | U12: 166.10491 | V12: 267.34005 | W12: =T12*1.2 -> 259.12367 | X12: 199.3259 | Y12: 360.90906 | Z12: =W12*Q12 -> 370017.27 | AA12: =X12*R12 -> 1707772 | AB12: =Y12*S12 -> 1885174.4 | AC12: =SUM(Z12:AB12) -> 3962963.7 | AD12: =VLOOKUP(A12,[1]Ark1!$A$3:$B$220, 2, FALSE) -> 5.5191 | AE12: =VLOOKUP(B12,[2]Data!$B$5:$BM$270, 64, FALSE) -> 1.7933606e+10 | AF12: =AD12/100*AE12 -> 9.8977366e+08 | AG12: =AC12/AF12*100 -> 0.40039091 | AH12: =IF(AG12<1, 1, 0) -> 1
A13: BURUNDI | B13: BDI | C13: SUB-SAHARAN AFRICA | D13: LOW INCOME | E13: 84636 | F13: 3950 | G13: 0 | H13: 88586 | I13: 1 | J13: 0.2181105 | K13: 0.17119193 | L13: IDA | M13: 0 | N13: 19321.536 | O13: 15165.208 | P13: 34486.745 | Q13: 2760.2195 | R13: 16561.317 | S13: 15165.208 | T13: =U13*1.3 -> 60.420806 | U13: 46.477543 | V13: 122.01188 | W13: =T13*1.2 -> 72.504967 | X13: 55.773052 | Y13: 164.71603 | Z13: =W13*Q13 -> 200129.62 | AA13: =X13*R13 -> 923675.19 | AB13: =Y13*S13 -> 2497952.9 | AC13: =SUM(Z13:AB13) -> 3621757.7 | AD13: =VLOOKUP(A13,[1]Ark1!$A$3:$B$220, 2, FALSE) -> 5.041 | AE13: =VLOOKUP(B13,[2]Data!$B$5:$BM$270, 64, FALSE) -> 2.6496803e+09 | AF13: =AD13/100*AE13 -> 1.3357038e+08 | AG13: =AC13/AF13*100 -> 2.7114976 | AH13: =IF(AG13<1, 1, 0) -> 0
A14: CAMEROON | B14: CMR | C14: SUB-SAHARAN AFRICA | D14: LOWER MIDDLE INCOME | E14: 473887 | F14: 9247 | G14: 0 | H14: 483134 | I14: 0.98 | J14: 0.25456694 | K14: 0.15065211 | L14: BLEND | M14: 0 | N14: 122989.94 | O14: 72785.158 | P14: 195775.1 | Q14: 17569.992 | R14: 105419.95 | S14: 72785.158 | T14: =U14*1.3 -> 132.20038 | U14: 101.6926 | V14: 324.32235 | W14: =T14*1.2 -> 158.64045 | X14: 122.03112 | Y14: 437.83518 | Z14: =W14*Q14 -> 2787311.5 | AA14: =X14*R14 -> 12864514 | AB14: =Y14*S14 -> 31867903 | AC14: =SUM(Z14:AB14) -> 47519728 | AD14: =VLOOKUP(A14,[1]Ark1!$A$3:$B$220, 2, FALSE) -> 3.1662 | AE14: =VLOOKUP(B14,[2]Data!$B$5:$BM$270, 64, FALSE) -> 4.0773241e+10 | AF14: =AD14/100*AE14 -> 1.2909624e+09 | AG14: =AC14/AF14*100 -> 3.6809538 | AH14: =IF(AG14<1, 1, 0) -> 0
A15: CENTRAL AFRICAN REPUBLIC | B15: CAF | C15: SUB-SAHARAN AFRICA | D15: LOW INCOME | E15: 11213 | F15: 470 | G15: 0 | H15: 11683 | I15: 1 | J15: 0.2539909 | K15: 0.13341657 | L15: IDA | M15: 0 | N15: 2967.3757 | O15: 1558.7058 | P15: 4526.0815 | Q15: 423.91082 | R15: 2543.4649 | S15: 1558.7058 | T15: =U15*1.3 -> 24.986 | U15: 19.22 | V15: 69.61 | W15: =T15*1.2 -> 29.9832 | X15: 23.064 | Y15: 93.9735 | Z15: =W15*Q15 -> 12710.203 | AA15: =X15*R15 -> 58662.474 | AB15: =Y15*S15 -> 146477.04 | AC15: =SUM(Z15:AB15) -> 217849.72 | AD15: =VLOOKUP(A15,[1]Ark1!$A$3:$B$220, 2, FALSE) -> 2.1667 | AE15: =VLOOKUP(B15,[2]Data!$B$5:$BM$270, 64, FALSE) -> 2.3267209e+09 | AF15: =AD15/100*AE15 -> 50413062 | AG15: =AC15/AF15*100 -> 0.43212951 | AH15: =IF(AG15<1, 1, 0) -> 1
A16: CHAD | B16: TCD | C16: SUB-SAHARAN AFRICA | D16: LOW INCOME | E16: 592764 | F16: 4953 | G16: 0 | H16: 597717 | I16: 0.94 | J16: 0.21558327 | K16: 0.14877422 | L16: IDA | M16: 0 | N16: 128857.78 | O16: 88924.879 | P16: 217782.66 | Q16: 18408.255 | R16: 110449.53 | S16: 88924.879 | T16: =U16*1.3 -> 66.205621 | U16: 50.9274 | V16: 135.69484 | W16: =T16*1.2 -> 79.446745 | X16: 61.112881 | Y16: 183.18804 | Z16: =W16*Q16 -> 1462475.9 | AA16: =X16*R16 -> 6749888.9 | AB16: =Y16*S16 -> 16289974 | AC16: =SUM(Z16:AB16) -> 24502339 | AD16: =VLOOKUP(A16,[1]Ark1!$A$3:$B$220, 2, FALSE) -> 2.9085 | AE16: =VLOOKUP(B16,[2]Data!$B$5:$BM$270, 64, FALSE) -> 1.0715396e+10 | AF16: =AD16/100*AE16 -> 3.1165729e+08 | AG16: =AC16/AF16*100 -> 7.8619494 | AH16: =IF(AG16<1, 1, 0) -> 0
A17: COLOMBIA | B17: COL | C17: LATIN AMERICA & CARIBBEAN | D17: UPPER MIDDLE INCOME | E17: 1607 | F17: 22675 | G17: 2500000 | H17: 2500000 | I17: 1 | J17: 0.10123878 | K17: 0.10126323 | L17: IBRD | M17: 0 | N17: 250884.28 | O17: 250944.87 | P17: 501829.15 | Q17: 35840.611 | R17: 215043.67 | S17: 250944.87 | T17: =U17*1.3 -> 2127.9124 | U17: 1636.8557 | V17: 1642.1891 | W17: =T17*1.2 -> 2553.4949 | X17: 1964.2269 | Y17: 2216.9553 | Z17: =W17*Q17 -> 91518818 | AA17: =X17*R17 -> 4.2239455e+08 | AB17: =Y17*S17 -> 5.5633356e+08 | AC17: =SUM(Z17:AB17) -> 1.0702469e+09 | AD17: =VLOOKUP(A17,[1]Ark1!$A$3:$B$220, 2, FALSE) -> 4.9331 | AE17: =VLOOKUP(B17,[2]Data!$B$5:$BM$270, 64, FALSE) -> 2.7015096e+11 | AF17: =AD17/100*AE17 -> 1.3326817e+10 | AG17: =AC17/AF17*100 -> 8.0307769 | AH17: =IF(AG17<1, 1, 0) -> 0
A18: CONGO | B18: COG | C18: SUB-SAHARAN AFRICA | D18: LOWER MIDDLE INCOME | E18: 41557 | F18: 18356 | G18: 0 | H18: 59913 | I18: 1 | J18: 0.17919965 | K18: 0.15925115 | L18: BLEND | M18: 0 | N18: 10736.389 | O18: 9541.2141 | P18: 20277.603 | Q18: 1533.7698 | R18: 9202.619 | S18: 9541.2141 | T18: =U18*1.3 -> 381.888 | U18: 293.76 | V18: 416.16 | W18: =T18*1.2 -> 458.2656 | X18: 352.512 | Y18: 561.816 | Z18: =W18*Q18 -> 702873.94 | AA18: =X18*R18 -> 3244033.6 | AB18: =Y18*S18 -> 5360406.7 | AC18: =SUM(Z18:AB18) -> 9307314.3 | AD18: 4.4486 | AE18: =VLOOKUP(B18,[2]Data!$B$5:$BM$270, 64, FALSE) -> 1.0483151e+10 | AF18: =AD18/100*AE18 -> 4.6635346e+08 | AG18: =AC18/AF18*100 -> 1.995764 | AH18: =IF(AG18<1, 1, 0) -> 0
A19: COSTA RICA | B19: CRI | C19: LATIN AMERICA & CARIBBEAN | D19: UPPER MIDDLE INCOME | E19: 14088 | F19: 239640 | G19: 16598 | H19: 270326 | I19: 0.5 | J19: 0.03953127 | K19: 0.03317803 | L19: IBRD | M19: 0 | N19: 10686.331 | O19: 8968.8847 | P19: 19655.215 | Q19: 1526.6187 | R19: 9159.712 | S19: 8968.8847 | T19: =U19*1.3 -> 3990.3458 | U19: 3069.4968 | V19: 3311.5171 | W19: =T19*1.2 -> 4788.415 | X19: 3683.3962 | Y19: 4470.5481 | Z19: =W19*Q19 -> 7310083.9 | AA19: =X19*R19 -> 33738848 | AB19: =Y19*S19 -> 40095830 | AC19: =SUM(Z19:AB19) -> 81144762 | AD19: =VLOOKUP(A19,[1]Ark1!$A$3:$B$220, 2, FALSE) -> 6.7107 | AE19: =VLOOKUP(B19,[2]Data!$B$5:$BM$270, 64, FALSE) -> 6.2395611e+10 | AF19: =AD19/100*AE19 -> 4.1871823e+09 | AG19: =AC19/AF19*100 -> 1.9379324 | AH19: =IF(AG19<1, 1, 0) -> 0
A20: DEMOCRATIC REPUBLIC OF THE CONGO | B20: COD | C20: SUB-SAHARAN AFRICA | D20: LOW INCOME | E20: 520544 | F20: 2147 | G20: 0 | H20: 522691 | I20: 1 | J20: 0.27513909 | K20: 0.17659794 | L20: IDA | M20: 0 | N20: 143812.72 | O20: 92306.156 | P20: 236118.88 | Q20: 20544.675 | R20: 123268.05 | S20: 92306.156 | T20: =U20*1.3 -> 60.672933 | U20: 46.671487 | V20: 41.092976 | W20: =T20*1.2 -> 72.807519 | X20: 56.005784 | Y20: 55.475518 | Z20: =W20*Q20 -> 1495806.8 | AA20: =X20*R20 -> 6903723.8 | AB20: =Y20*S20 -> 5120731.8 | AC20: =SUM(Z20:AB20) -> 13520262 | AD20: 1.6756 | AE20: =VLOOKUP(B20,[2]Data!$B$5:$BM$270, 64, FALSE) -> 4.8716962e+10 | AF20: =AD20/100*AE20 -> 8.1630141e+08 | AG20: =AC20/AF20*100 -> 1.6562831 | AH20: =IF(AG20<1, 1, 0) -> 0
A21: DJIBOUTI | B21: DJI | C21: MIDDLE EAST & NORTH AFRICA | D21: LOWER MIDDLE INCOME | E21: 20383 | F21: 9174 | G21: 0 | H21: 29557 | I21: 1 | J21: 0.18432027 | K21: 0.14929108 | L21: IDA | M21: 0 | N21: 5447.9541 | O21: 4412.5963 | P21: 9860.5505 | Q21: 778.27916 | R21: 4669.675 | S21: 4412.5963 | T21: =U21*1.3 -> 1277.5738 | U21: 982.74908 | V21: 19.108367 | W21: =T21*1.2 -> 1533.0886 | X21: 1179.2989 | Y21: 25.796295 | Z21: =W21*Q21 -> 1193170.9 | AA21: =X21*R21 -> 5506942.6 | AB21: =Y21*S21 -> 113828.64 | AC21: =SUM(Z21:AB21) -> 6813942.1 | AD21: =VLOOKUP(A21,[1]Ark1!$A$3:$B$220, 2, FALSE) -> 3.651 | AE21: =VLOOKUP(B21,[2]Data!$B$5:$BM$270, 64, FALSE) -> 3.1810712e+09 | AF21: =AD21/100*AE21 -> 1.1614091e+08 | AG21: =AC21/AF21*100 -> 5.8669613 | AH21: =IF(AG21<1, 1, 0) -> 0
A22: DOMINICAN REPUBLIC | B22: DOM | C22: LATIN AMERICA & CARIBBEAN | D22: UPPER MIDDLE INCOME | E22: 546 | F22: 2175 | G22: 113722 | H22: 116443 | J22: 0.18 | K22: 0.13 | L22: IBRD | M22: 1 | N22: 20959.74 | O22: 15137.59 | P22: 36097.33 | Q22: 2994.2486 | R22: 17965.491 | S22: 15137.59 | T22: =U22*1.3 -> 2474.6415 | U22: 1903.5704 | V22: 1327.6136 | W22: =T22*1.2 -> 2969.5699 | X22: 2284.2845 | Y22: 1792.2783 | Z22: =W22*Q22 -> 8891630.4 | AA22: =X22*R22 -> 41038293 | AB22: =Y22*S22 -> 27130774 | AC22: =SUM(Z22:AB22) -> 77060697 | AD22: =VLOOKUP(A22,[1]Ark1!$A$3:$B$220, 2, FALSE) -> 4.6187 | AE22: =VLOOKUP(B22,[2]Data!$B$5:$BM$270, 64, FALSE) -> 7.8844656e+10 | AF22: =AD22/100*AE22 -> 3.6415981e+09 | AG22: =AC22/AF22*100 -> 2.116123 | AH22: =IF(AG22<1, 1, 0) -> 0
A23: ECUADOR | B23: ECU | C23: LATIN AMERICA & CARIBBEAN | D23: UPPER MIDDLE INCOME | E23: 60125 | F23: 9754 | G23: 495304 | H23: 565183 | I23: 1 | J23: 0.03085239 | K23: 0.07258212 | L23: IBRD | M23: 0 | N23: 17437.247 | O23: 41022.181 | P23: 58459.427 | Q23: 2491.0353 | R23: 14946.212 | S23: 41022.181 | T23: =U23*1.3 -> 1021.9218 | U23: 786.09369 | V23: 468.64596 | W23: =T23*1.2 -> 1226.3062 | X23: 943.31243 | Y23: 632.67205 | Z23: =W23*Q23 -> 3054771.9 | AA23: =X23*R23 -> 14098948 | AB23: =Y23*S23 -> 25953587 | AC23: =SUM(Z23:AB23) -> 43107307 | AD23: =VLOOKUP(A23,[1]Ark1!$A$3:$B$220, 2, FALSE) -> 4.1341 | AE23: =VLOOKUP(B23,[2]Data!$B$5:$BM$270, 64, FALSE) -> 99291124000 | AF23: =AD23/100*AE23 -> 4.1047944e+09 | AG23: =AC23/AF23*100 -> 1.0501697 | AH23: =IF(AG23<1, 1, 0) -> 0
A24: EGYPT | B24: EGY | C24: MIDDLE EAST & NORTH AFRICA | D24: LOWER MIDDLE INCOME | E24: 294632 | F24: 63881 | G24: 0 | H24: 358513 | I24: 0.76 | J24: 0.12158897 | K24: 0.10286391 | L24: IBRD | M24: 0 | N24: 43591.225 | O24: 36878.05 | P24: 80469.274 | Q24: 6227.3178 | R24: 37363.907 | S24: 36878.05 | T24: =U24*1.3 -> 301.07172 | U24: 231.59363 | V24: 413.47688 | W24: =T24*1.2 -> 361.28606 | X24: 277.91236 | Y24: 558.19379 | Z24: =W24*Q24 -> 2249843.1 | AA24: =X24*R24 -> 10383891 | AB24: =Y24*S24 -> 20585098 | AC24: =SUM(Z24:AB24) -> 33218833 | AD24: 3.9676 | AE24: =VLOOKUP(B24,[2]Data!$B$5:$BM$270, 64, FALSE) -> 3.8381784e+11 | AF24: =AD24/100*AE24 -> 1.5228357e+10 | AG24: =AC24/AF24*100 -> 0.218138 | AH24: =IF(AG24<1, 1, 0) -> 1
A25: ETHIOPIA | B25: ETH | C25: SUB-SAHARAN AFRICA | D25: LOW INCOME | E25: 879598 | F25: 2214 | G25: 0 | H25: 881812 | I25: 1 | J25: 0.25243805 | K25: 0.18253793 | L25: IDA | M25: 0 | N25: 222602.9 | O25: 160964.14 | P25: 383567.04 | Q25: 31800.414 | R25: 190802.48 | S25: 160964.14 | T25: =U25*1.3 -> 85.714618 | U25: 65.934321 | V25: 142.83694 | W25: =T25*1.2 -> 102.85754 | X25: 79.121185 | Y25: 192.82987 | Z25: =W25*Q25 -> 3270912.4 | AA25: =X25*R25 -> 15096518 | AB25: =Y25*S25 -> 31038694 | AC25: =SUM(Z25:AB25) -> 49406124 | AD25: =VLOOKUP(A25,[1]Ark1!$A$3:$B$220, 2, FALSE) -> 5.5763 | AE25: =VLOOKUP(B25,[2]Data!$B$5:$BM$270, 64, FALSE) -> 1.0765773e+11 | AF25: =AD25/100*AE25 -> 6.0033182e+09 | AG25: =AC25/AF25*100 -> 0.82298027 | AH25: =IF(AG25<1, 1, 0) -> 1
A26: GEORGIA | B26: GEO | C26: EUROPE & CENTRAL ASIA | D26: UPPER MIDDLE INCOME | E26: 27839 | F26: 1030 | G26: 0 | H26: 28869 | I26: 1 | J26: 0.11006142 | K26: 0.07119509 | L26: IBRD | M26: 0 | N26: 3177.3633 | O26: 2055.3309 | P26: 5232.6942 | Q26: 453.90904 | R26: 2723.4542 | S26: 2055.3309 | T26: =U26*1.3 -> 758.212 | U26: 583.24 | V26: 901.37 | W26: =T26*1.2 -> 909.8544 | X26: 699.888 | Y26: 1216.8495 | Z26: =W26*Q26 -> 412991.14 | AA26: =X26*R26 -> 1906112.9 | AB26: =Y26*S26 -> 2501028.4 | AC26: =SUM(Z26:AB26) -> 4820132.4 | AD26: =VLOOKUP(A26,[1]Ark1!$A$3:$B$220, 2, FALSE) -> 3.8501 | AE26: =VLOOKUP(B26,[2]Data!$B$5:$BM$270, 64, FALSE) -> 1.5842923e+10 | AF26: =AD26/100*AE26 -> 6.0996836e+08 | AG26: =AC26/AF26*100 -> 0.79022663 | AH26: =IF(AG26<1, 1, 0) -> 1
A27: GHANA | B27: GHA | C27: SUB-SAHARAN AFRICA | D27: LOWER MIDDLE INCOME | E27: 8531 | F27: 2517 | G27: 0 | H27: 11048 | I27: 1 | J27: 0.1145235 | K27: 0.12237721 | L27: IDA | M27: 0 | N27: 1265.2557 | O27: 1352.0234 | P27: 2617.2791 | Q27: 180.75081 | R27: 1084.5048 | S27: 1352.0234 | T27: =U27*1.3 -> 272.64784 | U27: 209.72911 | V27: 595.30109 | W27: =T27*1.2 -> 327.17741 | X27: 251.67493 | Y27: 803.65647 | Z27: =W27*Q27 -> 59137.581 | AA27: =X27*R27 -> 272942.67 | AB27: =Y27*S27 -> 1086562.4 | AC27: =SUM(Z27:AB27) -> 1418642.6 | AD27: =VLOOKUP(A27,[1]Ark1!$A$3:$B$220, 2, FALSE) -> 3.9111 | AE27: =VLOOKUP(B27,[2]Data!$B$5:$BM$270, 64, FALSE) -> 7.0043096e+10 | AF27: =AD27/100*AE27 -> 2.7394555e+09 | AG27: =AC27/AF27*100 -> 0.051785568 | AH27: =IF(AG27<1, 1, 0) -> 1
A28: INDIA | B28: IND | C28: SOUTH ASIA | D28: LOWER MIDDLE INCOME | E28: 242835 | F28: 15794 | G28: 0 | H28: 258629 | I28: 0.14 | J28: 0.18 | K28: 0.13 | L28: IBRD | M28: 1 | N28: 46553.22 | O28: 33621.77 | P28: 80174.99 | Q28: 6650.46 | R28: 39902.76 | S28: 33621.77 | T28: =U28*1.3 -> 369.87273 | U28: 284.51749 | V28: 351.72918 | W28: =T28*1.2 -> 443.84728 | X28: 341.42098 | Y28: 474.8344 | Z28: =W28*Q28 -> 2951788.6 | AA28: =X28*R28 -> 13623640 | AB28: =Y28*S28 -> 15964773 | AC28: =SUM(Z28:AB28) -> 32540201 | AD28: =VLOOKUP(A28,[1]Ark1!$A$3:$B$220, 2, FALSE) -> 4.4742 | AE28: =VLOOKUP(B28,[2]Data!$B$5:$BM$270, 64, FALSE) -> 2.6715954e+12 | AF28: =AD28/100*AE28 -> 1.1953252e+11 | AG28: =AC28/AF28*100 -> 0.027222885 | AH28: =IF(AG28<1, 1, 0) -> 1
A29: INDONESIA | B29: IDN | C29: EAST ASIA & PACIFIC | D29: UPPER MIDDLE INCOME | E29: 9785 | F29: 2889 | G29: 0 | H29: 12674 | I29: 1 | J29: 0.10413899 | K29: 0.07920286 | L29: IBRD | M29: 0 | N29: 1319.8575 | O29: 1003.8171 | P29: 2323.6746 | Q29: 188.55108 | R29: 1131.3065 | S29: 1003.8171 | T29: =U29*1.3 -> 925.92539 | U29: 712.2503 | V29: 765.58807 | W29: =T29*1.2 -> 1111.1105 | X29: 854.70036 | Y29: 1033.5439 | Z29: =W29*Q29 -> 209501.08 | AA29: =X29*R29 -> 966928.07 | AB29: =Y29*S29 -> 1037489 | AC29: =SUM(Z29:AB29) -> 2213918.2 | AD29: =VLOOKUP(A29,[1]Ark1!$A$3:$B$220, 2, FALSE) -> 2.815 | AE29: =VLOOKUP(B29,[2]Data!$B$5:$BM$270, 64, FALSE) -> 1.0590548e+12 | AF29: =AD29/100*AE29 -> 2.9812394e+10 | AG29: =AC29/AF29*100 -> 0.0074261671 | AH29: =IF(AG29<1, 1, 0) -> 1
A30: IRAN (ISLAMIC REPUBLIC OF) | B30: IRN | C30: MIDDLE EAST & NORTH AFRICA | D30: LOWER MIDDLE INCOME | E30: 3400000 | F30: 34 | G30: 0 | H30: 3400000 | I30: 1 | J30: 0.18892316 | K30: 0.13239648 | L30: IBRD | M30: 0 | N30: 647085.42 | O30: 453474.5 | P30: 1100559.9 | Q30: 92440.775 | R30: 554644.65 | S30: 453474.5 | T30: =U30*1.3 -> 587.38146 | U30: 451.83189 | V30: 629.40597 | W30: =T30*1.2 -> 704.85775 | X30: 542.19827 | Y30: 849.69806 | Z30: =W30*Q30 -> 65157596 | AA30: =X30*R30 -> 3.0072737e+08 | AB30: =Y30*S30 -> 3.853164e+08 | AC30: =SUM(Z30:AB30) -> 7.5120137e+08 | AD30: 3.5924 | AE30: =VLOOKUP(B30,[2]Data!$B$5:$BM$270, 64, FALSE) -> 2.3973549e+11 | AF30: =AD30/100*AE30 -> 8.6122576e+09 | AG30: =AC30/AF30*100 -> 8.7224674 | AH30: =IF(AG30<1, 1, 0) -> 0
A31: IRAQ | B31: IRQ | C31: MIDDLE EAST & NORTH AFRICA | D31: UPPER MIDDLE INCOME | E31: 273716 | F31: 10621 | G31: 0 | H31: 284337 | I31: 1 | J31: 0.19269243 | K31: 0.10273057 | L31: IBRD | M31: 0 | N31: 54789.586 | O31: 29210.101 | P31: 83999.688 | Q31: 7827.0838 | R31: 46962.503 | S31: 29210.101 | T31: =U31*1.3 -> 417.37113 | U31: 321.05471 | V31: 1023.7962 | W31: =T31*1.2 -> 500.84535 | X31: 385.26565 | Y31: 1382.1248 | Z31: =W31*Q31 -> 3920158.5 | AA31: =X31*R31 -> 18093039 | AB31: =Y31*S31 -> 40372006 | AC31: =SUM(Z31:AB31) -> 62385204 | AE31: =VLOOKUP(B31,[2]Data!$B$5:$BM$270, 64, FALSE) -> 1.8092409e+11
A32: JORDAN | B32: JOR | C32: MIDDLE EAST & NORTH AFRICA | D32: LOWER MIDDLE INCOME | E32: 697761 | F32: 45177 | G32: 0 | H32: 742938 | I32: 1 | J32: 0.20370585 | K32: 0.15155333 | L32: IBRD | M32: 0 | N32: 151340.82 | O32: 112594.72 | P32: 263935.54 | Q32: 21620.117 | R32: 129720.7 | S32: 112594.72 | T32: =U32*1.3 -> 1151.309 | U32: 885.62233 | V32: 877.65694 | W32: =T32*1.2 -> 1381.5708 | X32: 1062.7468 | Y32: 1184.8369 | Z32: =W32*Q32 -> 29869723 | AA32: =X32*R32 -> 1.3786026e+08 | AB32: =Y32*S32 -> 1.3340637e+08 | AC32: =SUM(Z32:AB32) -> 3.0113636e+08 | AD32: =VLOOKUP(A32,[1]Ark1!$A$3:$B$220, 2, FALSE) -> 2.9379 | AE32: =VLOOKUP(B32,[2]Data!$B$5:$BM$270, 64, FALSE) -> 4.3579916e+10 | AF32: =AD32/100*AE32 -> 1.2803344e+09 | AG32: =AC32/AF32*100 -> 23.520134 | AH32: =IF(AG32<1, 1, 0) -> 0
A33: KENYA | B33: KEN | C33: SUB-SAHARAN AFRICA | D33: LOWER MIDDLE INCOME | E33: 504473 | F33: 69011 | G33: 0 | H33: 573484 | I33: 1 | J33: 0.22335784 | K33: 0.18356978 | L33: BLEND | M33: 0 | N33: 128092.15 | O33: 105274.33 | P33: 233366.48 | Q33: 18298.878 | R33: 109793.27 | S33: 105274.33 | T33: =U33*1.3 -> 272.14707 | U33: 209.3439 | V33: 455.55 | W33: =T33*1.2 -> 326.57648 | X33: 251.21268 | Y33: 614.9925 | Z33: =W33*Q33 -> 5975983.2 | AA33: =X33*R33 -> 27581461 | AB33: =Y33*S33 -> 64742923 | AC33: =SUM(Z33:AB33) -> 98300368 | AD33: =VLOOKUP(A33,[1]Ark1!$A$3:$B$220, 2, FALSE) -> 5.08 | AE33: =VLOOKUP(B33,[2]Data!$B$5:$BM$270, 64, FALSE) -> 1.0065751e+11 | AF33: =AD33/100*AE33 -> 5.1134013e+09 | AG33: =AC33/AF33*100 -> 1.9224067 | AH33: =IF(AG33<1, 1, 0) -> 0
A34: LEBANON | B34: LBN | C34: MIDDLE EAST & NORTH AFRICA | D34: LOWER MIDDLE INCOME | E34: 818861 | F34: 7995 | G34: 0 | H34: 826856 | I34: 1 | J34: 0.24069653 | K34: 0.17162009 | L34: IBRD | M34: 0 | N34: 199021.37 | O34: 141905.1 | P34: 340926.47 | Q34: 28431.624 | R34: 170589.74 | S34: 141905.1 | T34: =U34*1.3 -> 1893.8364 | U34: 1456.7973 | V34: 1501.8227 | W34: =T34*1.2 -> 2272.6037 | X34: 1748.1567 | Y34: 2027.4606 | Z34: =W34*Q34 -> 64613815 | AA34: =X34*R34 -> 2.982176e+08 | AB34: =Y34*S34 -> 2.87707e+08 | AC34: =SUM(Z34:AB34) -> 6.5053842e+08 | AE34: =VLOOKUP(B34,[2]Data!$B$5:$BM$270, 64, FALSE) -> 3.1712128e+10
A35: LIBYA | B35: LBY | C35: MIDDLE EAST & NORTH AFRICA | D35: UPPER MIDDLE INCOME | E35: 2208 | F35: 42509 | G35: 0 | H35: 44717 | I35: 1 | J35: 0.17074275 | K35: 0.12681159 | L35: IBRD | M35: 0 | N35: 7635.1037 | O35: 5670.6341 | P35: 13305.738 | Q35: 1090.7291 | R35: 6544.3746 | S35: 5670.6341 | T35: =U35*1.3 -> 1879.9704 | U35: 1446.1311 | V35: 1196.5709 | W35: =T35*1.2 -> 2255.9645 | X35: 1735.3573 | Y35: 1615.3707 | Z35: =W35*Q35 -> 2460646.2 | AA35: =X35*R35 -> 11356828 | AB35: =Y35*S35 -> 9160176.4 | AC35: =SUM(Z35:AB35) -> 22977651 | AE35: =VLOOKUP(B35,[2]Data!$B$5:$BM$270, 64, FALSE) -> 4.6808209e+10
A36: MALAWI | B36: MWI | C36: SUB-SAHARAN AFRICA | D36: LOW INCOME | E36: 35162 | F36: 21263 | G36: 0 | H36: 56425 | I36: 1 | J36: 0.2117627 | K36: 0.14817132 | L36: IDA | M36: 0 | N36: 11948.71 | O36: 8360.5668 | P36: 20309.277 | Q36: 1706.9586 | R36: 10241.752 | S36: 8360.5668 | T36: =U36*1.3 -> 73.163262 | U36: 56.279432 | V36: 178.70402 | W36: =T36*1.2 -> 87.795914 | X36: 67.535319 | Y36: 241.25043 | Z36: =W36*Q36 -> 149863.99 | AA36: =X36*R36 -> 691679.99 | AB36: =Y36*S36 -> 2016990.3 | AC36: =SUM(Z36:AB36) -> 2858534.3 | AD36: =VLOOKUP(A36,[1]Ark1!$A$3:$B$220, 2, FALSE) -> 2.9076 | AE36: =VLOOKUP(B36,[2]Data!$B$5:$BM$270, 64, FALSE) -> 1.2056109e+10 | AF36: =AD36/100*AE36 -> 3.5054342e+08 | AG36: =AC36/AF36*100 -> 0.81545798 | AH36: =IF(AG36<1, 1, 0) -> 1
A37: MALAYSIA | B37: MYS | C37: EAST ASIA & PACIFIC | D37: UPPER MIDDLE INCOME | E37: 134554 | F37: 47433 | G37: 0 | H37: 181987 | I37: 1 | J37: 0.14148966 | K37: 0.0569957 | L37: IBRD | M37: 0 | N37: 25749.279 | O37: 10372.477 | P37: 36121.756 | Q37: 3678.4684 | R37: 22070.811 | S37: 10372.477 | T37: =U37*1.3 -> 2657.6555 | U37: 2044.3504 | V37: 2482.2852 | W37: =T37*1.2 -> 3189.1866 | X37: 2453.2205 | Y37: 3351.085 | Z37: =W37*Q37 -> 11731322 | AA37: =X37*R37 -> 54144565 | AB37: =Y37*S37 -> 34759052 | AC37: =SUM(Z37:AB37) -> 1.0063494e+08 | AD37: =VLOOKUP(A37,[1]Ark1!$A$3:$B$220, 2, FALSE) -> 3.917 | AE37: =VLOOKUP(B37,[2]Data!$B$5:$BM$270, 64, FALSE) -> 3.3733946e+11 | AF37: =AD37/100*AE37 -> 1.3213587e+10 | AG37: =AC37/AF37*100 -> 0.76160199 | AH37: =IF(AG37<1, 1, 0) -> 1
A38: MALI | B38: MLI | C38: SUB-SAHARAN AFRICA | D38: LOW INCOME | E38: 60637 | F38: 880 | G38: 0 | H38: 61517 | I38: 1 | J38: 0.25766446 | K38: 0.1261441 | L38: IDA | M38: 0 | N38: 15850.745 | O38: 7760.0068 | P38: 23610.752 | Q38: 2264.3921 | R38: 13586.353 | S38: 7760.0068 | T38: =U38*1.3 -> 285.48128 | U38: 219.60098 | V38: 260.00971 | W38: =T38*1.2 -> 342.57753 | X38: 263.52118 | Y38: 351.01311 | Z38: =W38*Q38 -> 775729.86 | AA38: =X38*R38 -> 3580291.7 | AB38: =Y38*S38 -> 2723864.1 | AC38: =SUM(Z38:AB38) -> 7079885.7 | AD38: =VLOOKUP(A38,[1]Ark1!$A$3:$B$220, 2, FALSE) -> 3.7634 | AE38: =VLOOKUP(B38,[2]Data!$B$5:$BM$270, 64, FALSE) -> 1.7465393e+10 | AF38: =AD38/100*AE38 -> 6.5729259e+08 | AG38: =AC38/AF38*100 -> 1.0771285 | AH38: =IF(AG38<1, 1, 0) -> 0
A39: MAURITANIA | B39: MRT | C39: SUB-SAHARAN AFRICA | D39: LOWER MIDDLE INCOME | E39: 100981 | F39: 5389 | G39: 0 | H39: 106370 | I39: 1 | J39: 0.23612363 | K39: 0.1433438 | L39: IDA | M39: 0 | N39: 25116.47 | O39: 15247.48 | P39: 40363.95 | Q39: 3588.0672 | R39: 21528.403 | S39: 15247.48 | T39: =U39*1.3 -> 159.22933 | U39: 122.4841 | V39: 251.38985 | W39: =T39*1.2 -> 191.0752 | X39: 146.98092 | Y39: 339.37629 | Z39: =W39*Q39 -> 685590.65 | AA39: =X39*R39 -> 3164264.5 | AB39: =Y39*S39 -> 5174633.2 | AC39: =SUM(Z39:AB39) -> 9024488.4 | AD39: =VLOOKUP(A39,[1]Ark1!$A$3:$B$220, 2, FALSE) -> 1.8812 | AE39: =VLOOKUP(B39,[2]Data!$B$5:$BM$270, 64, FALSE) -> 8.4054987e+09 | AF39: =AD39/100*AE39 -> 1.5812424e+08 | AG39: =AC39/AF39*100 -> 5.7072137 | AH39: =IF(AG39<1, 1, 0) -> 0
A40: MEXICO | B40: MEX | C40: LATIN AMERICA & CARIBBEAN | D40: UPPER MIDDLE INCOME | E40: 95579 | F40: 210609 | G40: 53027 | H40: 359215 | I40: 1 | J40: 0.12190962 | K40: 0.08450601 | L40: IBRD | M40: 0 | N40: 43791.766 | O40: 30355.827 | P40: 74147.592 | Q40: 6255.9665 | R40: 37535.799 | S40: 30355.827 | T40: =U40*1.3 -> 1964.3411 | U40: 1511.0316 | V40: 1516.6024 | W40: =T40*1.2 -> 2357.2093 | X40: 1813.2379 | Y40: 2047.4133 | Z40: =W40*Q40 -> 14746622 | AA40: =X40*R40 -> 68061333 | AB40: =Y40*S40 -> 62150923 | AC40: =SUM(Z40:AB40) -> 1.4495888e+08 | AD40: =VLOOKUP(A40,[1]Ark1!$A$3:$B$220, 2, FALSE) -> 4.7275 | AE40: =VLOOKUP(B40,[2]Data!$B$5:$BM$270, 64, FALSE) -> 1.090515e+12 | AF40: =AD40/100*AE40 -> 5.1554095e+10 | AG40: =AC40/AF40*100 -> 0.2811782 | AH40: =IF(AG40<1, 1, 0) -> 1
...

Sheet Targets
B2: Country | C2: Code | D2: Income Grp | E2: # Refugee Children | J2: Per Capita Cost of Inclusive Education (US$) | M2: Host Country GER | Q2: Refugee GER | T2: SDG National Benchmarks (2030) | X2: Refugee GER - Targets | AB2: Total Refugee Children Reached | AG2: Total Annual Cost (US$M)
E3: KG | F3: Primary | G3: Lower Secondary | H3: Upper Secondary | I3: Total | J3: KG | K3: Primary | L3: Secondary | M3: KG | N3: Prm | O3: LS | P3: US | Q3: KG | R3: Prm | S3: Sec | T3: KG | U3: Prm | V3: LS | W3: US | X3: KG | Y3: Prm | Z3: LS | AA3: US | AB3: KG | AC3: Primary | AD3: Lower Secondary | AE3: Upper Secondary | AF3: Total | AG3: KG | AH3: Primary | AI3: Lower Secondary | AJ3: Upper Secondary | AK3: Total
B4: TüRKIYE | C4: TUR | D4: UMIC | E4: 105702.27 | F4: 634213.61 | G4: 234914.66 | H4: 234914.66 | I4: 1209745.2 | J4: 1939.7782 | K4: 1551.8225 | L4: 2000.4987 | M4: 39.74593 | N4: 102.6 | O4: 101.15 | P4: 127.68 | Q4: =VLOOKUP($C4,'Refugee GER'!$B$2:$G$73,4, FALSE) -> 0.34337712 | R4: =VLOOKUP($C4,'Refugee GER'!$B$2:$G$73,5, FALSE) -> 0.75128249 | S4: =VLOOKUP($C4,'Refugee GER'!$B$2:$G$73,6, FALSE) -> 0.6396274 | T4: 77.558075 | U4: 99.604701 | V4: 97.103452 | W4: 91.16484 | X4: 100 | Y4: 99.604701 | Z4: 100 | AA4: 100 | AB4: =X4/100*E4 -> 105702.27 | AC4: =Y4/100*F4 -> 631706.57 | AD4: =Z4/100*G4 -> 234914.66 | AE4: =AA4/100*H4 -> 234914.66 | AF4: =SUM(AB4:AE4) -> 1207238.2 | AG4: =AB4*J4/1000000 -> 205.03895 | AH4: =AC4*K4/1000000 -> 980.2965 | AI4: =AD4*L4/1000000 -> 469.94647 | AJ4: =AE4*L4/1000000 -> 469.94647 | AK4: =SUM(AG4:AJ4) -> 2125.2284
B5: IRAN (ISLAMIC REPUBLIC OF) | C5: IRN | D5: LMIC | E5: 92440.775 | F5: 554644.65 | G5: 226737.25 | H5: 226737.25 | I5: 1100559.9 | J5: 677.74783 | K5: 542.19827 | L5: 849.69806 | M5: 72.476547 | N5: 104.48 | O5: 93.84 | P5: 79.73 | Q5: =VLOOKUP($C5,'Refugee GER'!$B$2:$G$73,4, FALSE) -> - | R5: =VLOOKUP($C5,'Refugee GER'!$B$2:$G$73,5, FALSE) -> 0.88 | S5: =VLOOKUP($C5,'Refugee GER'!$B$2:$G$73,6, FALSE) -> 0.73 | T5: 95.217848 | U5: 99.604701 | V5: 96.70693 | W5: 83.047278 | X5: 100 | Y5: 99.604701 | Z5: 100 | AA5: 100 | AB5: =X5/100*E5 -> 92440.775 | AC5: =Y5/100*F5 -> 552452.15 | AD5: =Z5/100*G5 -> 226737.25 | AE5: =AA5/100*H5 -> 226737.25 | AF5: =SUM(AB5:AE5) -> 1098367.4 | AG5: =AB5*J5/1000000 -> 62.651535 | AH5: =AC5*K5/1000000 -> 299.5386 | AI5: =AD5*L5/1000000 -> 192.6582 | AJ5: =AE5*L5/1000000 -> 192.6582 | AK5: =SUM(AG5:AJ5) -> 747.50654
B6: UGANDA | C6: UGA | D6: LIC | E6: 51558.814 | F6: 309352.88 | G6: 133533.24 | H6: 133533.24 | I6: 627978.18 | J6: 65.164665 | K6: 52.131732 | L6: 146.18646 | M6: 20.14646 | N6: 105.53 | O6: 30.43 | P6: 9.73 | Q6: =VLOOKUP($C6,'Refugee GER'!$B$2:$G$73,4, FALSE) -> 0.39496804 | R6: =VLOOKUP($C6,'Refugee GER'!$B$2:$G$73,5, FALSE) -> 0.86380566 | S6: =VLOOKUP($C6,'Refugee GER'!$B$2:$G$73,6, FALSE) -> 0.095342737 | T6: 69.120705 | U6: 91.224338 | V6: 85.967889 | W6: 66.141795 | X6: 100 | Y6: 99.604701 | Z6: 100 | AA6: 100 | AB6: =X6/100*E6 -> 51558.814 | AC6: =Y6/100*F6 -> 308130.02 | AD6: =Z6/100*G6 -> 133533.24 | AE6: =AA6/100*H6 -> 133533.24 | AF6: =SUM(AB6:AE6) -> 626755.31 | AG6: =AB6*J6/1000000 -> 3.3598128 | AH6: =AC6*K6/1000000 -> 16.063351 | AI6: =AD6*L6/1000000 -> 19.520752 | AJ6: =AE6*L6/1000000 -> 19.520752 | AK6: =SUM(AG6:AJ6) -> 58.464668
B7: PAKISTAN | C7: PAK | D7: LMIC | E7: 49256.555 | F7: 295539.33 | G7: 105883.27 | H7: 105883.27 | I7: 556562.43 | J7: 320.54966 | K7: 256.43973 | L7: 549.84445 | M7: 82.556671 | N7: 84.37 | O7: 50.91 | P7: 34.58 | Q7: =VLOOKUP($C7,'Refugee GER'!$B$2:$G$73,4, FALSE) -> 0.11217083 | R7: =VLOOKUP($C7,'Refugee GER'!$B$2:$G$73,5, FALSE) -> 0.10205199 | S7: =VLOOKUP($C7,'Refugee GER'!$B$2:$G$73,6, FALSE) -> 0.032401556 | T7: 95.342499 | U7: 100 | V7: 100 | W7: 100 | X7: 100 | Y7: 99.604701 | Z7: 100 | AA7: 100 | AB7: =X7/100*E7 -> 49256.555 | AC7: =Y7/100*F7 -> 294371.07 | AD7: =Z7/100*G7 -> 105883.27 | AE7: =AA7/100*H7 -> 105883.27 | AF7: =SUM(AB7:AE7) -> 555394.17 | AG7: =AB7*J7/1000000 -> 15.789172 | AH7: =AC7*K7/1000000 -> 75.488438 | AI7: =AD7*L7/1000000 -> 58.21933 | AJ7: =AE7*L7/1000000 -> 58.21933 | AK7: =SUM(AG7:AJ7) -> 207.71627
B8: COLOMBIA | C8: COL | D8: UMIC | E8: 35840.611 | F8: 215043.67 | G8: 125472.44 | H8: 125472.44 | I8: 501829.15 | J8: 2455.2836 | K8: 1964.2269 | L8: 2216.9553 | M8: 85.928322 | N8: 106.49 | O8: 109.88 | P8: 89.43 | Q8: =VLOOKUP($C8,'Refugee GER'!$B$2:$G$73,4, FALSE) -> - | R8: =VLOOKUP($C8,'Refugee GER'!$B$2:$G$73,5, FALSE) -> 0.53016469 | S8: =VLOOKUP($C8,'Refugee GER'!$B$2:$G$73,6, FALSE) -> 0.22220363 | T8: 100 | U8: 97.3 | V8: 100 | W8: 85.9 | X8: 100 | Y8: 99.604701 | Z8: 100 | AA8: 100 | AB8: =X8/100*E8 -> 35840.611 | AC8: =Y8/100*F8 -> 214193.6 | AD8: =Z8/100*G8 -> 125472.44 | AE8: =AA8/100*H8 -> 125472.44 | AF8: =SUM(AB8:AE8) -> 500979.09 | AG8: =AB8*J8/1000000 -> 87.998864 | AH8: =AC8*K8/1000000 -> 420.72483 | AI8: =AD8*L8/1000000 -> 278.16679 | AJ8: =AE8*L8/1000000 -> 278.16679 | AK8: =SUM(AG8:AJ8) -> 1065.0573
B9: PERU | C9: PER | D9: UMIC | E9: 38926.826 | F9: 233560.95 | G9: 98398.365 | H9: 98398.365 | I9: 469284.51 | J9: 1623.7369 | K9: 1298.9895 | L9: 1877.376 | M9: 96.44178 | N9: 107.66 | O9: 101.94 | P9: 94.84 | Q9: =VLOOKUP($C9,'Refugee GER'!$B$2:$G$73,4, FALSE) -> - | R9: =VLOOKUP($C9,'Refugee GER'!$B$2:$G$73,5, FALSE) -> 0.42018735 | S9: =VLOOKUP($C9,'Refugee GER'!$B$2:$G$73,6, FALSE) -> 0.30591971 | T9: 95.217848 | U9: 99.20299 | V9: 97.28275 | W9: 91.16484 | X9: 100 | Y9: 99.604701 | Z9: 100 | AA9: 100 | AB9: =X9/100*E9 -> 38926.826 | AC9: =Y9/100*F9 -> 232637.69 | AD9: =Z9/100*G9 -> 98398.365 | AE9: =AA9/100*H9 -> 98398.365 | AF9: =SUM(AB9:AE9) -> 468361.25 | AG9: =AB9*J9/1000000 -> 63.206924 | AH9: =AC9*K9/1000000 -> 302.19393 | AI9: =AD9*L9/1000000 -> 184.73073 | AJ9: =AE9*L9/1000000 -> 184.73073 | AK9: =SUM(AG9:AJ9) -> 734.86231
B10: SUDAN | C10: SDN | D10: LIC | E10: 35940.747 | F10: 215644.48 | G10: 86858.398 | H10: 86858.398 | I10: 425302.02 | J10: 254.93466 | K10: 203.94773 | L10: 210.50407 | M10: 47.39994 | N10: 77.77 | O10: 59.22 | P10: 40.87 | Q10: =VLOOKUP($C10,'Refugee GER'!$B$2:$G$73,4, FALSE) -> 0.03274802 | R10: =VLOOKUP($C10,'Refugee GER'!$B$2:$G$73,5, FALSE) -> 0.30468948 | S10: =VLOOKUP($C10,'Refugee GER'!$B$2:$G$73,6, FALSE) -> 0.068999705 | T10: 63.200001 | U10: 95 | V10: 90 | W10: 80 | X10: 100 | Y10: 99.604701 | Z10: 100 | AA10: 100 | AB10: =X10/100*E10 -> 35940.747 | AC10: =Y10/100*F10 -> 214792.04 | AD10: =Z10/100*G10 -> 86858.398 | AE10: =AA10/100*H10 -> 86858.398 | AF10: =SUM(AB10:AE10) -> 424449.59 | AG10: =AB10*J10/1000000 -> 9.1625422 | AH10: =AC10*K10/1000000 -> 43.806349 | AI10: =AD10*L10/1000000 -> 18.284046 | AJ10: =AE10*L10/1000000 -> 18.284046 | AK10: =SUM(AG10:AJ10) -> 89.536983
B11: RUSSIAN FEDERATION | C11: RUS | D11: UMIC | E11: 32881.834 | F11: 197291.01 | G11: 83117.97 | H11: 83117.97 | I11: 396408.78 | J11: 3841.2658 | K11: 3073.0126 | L11: 3267.6796 | M11: 85.993156 | N11: 104.13 | O11: 100.66 | P11: 107.8 | Q11: =VLOOKUP($C11,'Refugee GER'!$B$2:$G$73,4, FALSE) -> - | R11: =VLOOKUP($C11,'Refugee GER'!$B$2:$G$73,5, FALSE) -> - | S11: =VLOOKUP($C11,'Refugee GER'!$B$2:$G$73,6, FALSE) -> - | T11: 98.300003 | U11: 98.8 | V11: 98.9 | W11: 96.5 | X11: 100 | Y11: 99.604701 | Z11: 100 | AA11: 100 | AB11: =X11/100*E11 -> 32881.834 | AC11: =Y11/100*F11 -> 196511.12 | AD11: =Z11/100*G11 -> 83117.97 | AE11: =AA11/100*H11 -> 83117.97 | AF11: =SUM(AB11:AE11) -> 395628.89 | AG11: =AB11*J11/1000000 -> 126.30786 | AH11: =AC11*K11/1000000 -> 603.88114 | AI11: =AD11*L11/1000000 -> 271.60289 | AJ11: =AE11*L11/1000000 -> 271.60289 | AK11: =SUM(AG11:AJ11) -> 1273.3948
B12: ETHIOPIA | C12: ETH | D12: LIC | E12: 31800.414 | F12: 190802.48 | G12: 80482.069 | H12: 80482.069 | I12: 383567.04 | J12: 98.901482 | K12: 79.121185 | L12: 192.82987 | M12: 30.118839 | N12: 85.53 | O12: 47.71 | P12: 31.58801 | Q12: =VLOOKUP($C12,'Refugee GER'!$B$2:$G$73,4, FALSE) -> 0.40753682 | R12: =VLOOKUP($C12,'Refugee GER'!$B$2:$G$73,5, FALSE) -> 0.53575945 | S12: =VLOOKUP($C12,'Refugee GER'!$B$2:$G$73,6, FALSE) -> 0.19805083 | T12: 100 | U12: 99 | V12: 99 | W12: 75 | X12: 100 | Y12: 99.604701 | Z12: 100 | AA12: 100 | AB12: =X12/100*E12 -> 31800.414 | AC12: =Y12/100*F12 -> 190048.24 | AD12: =Z12/100*G12 -> 80482.069 | AE12: =AA12/100*H12 -> 80482.069 | AF12: =SUM(AB12:AE12) -> 382812.8 | AG12: =AB12*J12/1000000 -> 3.1451081 | AH12: =AC12*K12/1000000 -> 15.036842 | AI12: =AD12*L12/1000000 -> 15.519347 | AJ12: =AE12*L12/1000000 -> 15.519347 | AK12: =SUM(AG12:AJ12) -> 49.220644
B13: BANGLADESH | C13: BGD | D13: LMIC | E13: 30302.621 | F13: 181815.72 | G13: 66971.188 | H13: 66971.188 | I13: 346060.72 | J13: 231.06375 | K13: 184.851 | L13: 198.78258 | M13: 36.380688 | N13: 117.66 | O13: 85.52 | P13: 62.2 | Q13: =VLOOKUP($C13,'Refugee GER'!$B$2:$G$73,4, FALSE) -> 0.45280469 | R13: =VLOOKUP($C13,'Refugee GER'!$B$2:$G$73,5, FALSE) -> 0.28483199 | S13: =VLOOKUP($C13,'Refugee GER'!$B$2:$G$73,6, FALSE) -> 0.0059634212 | T13: 100 | U13: 100 | V13: 92.5 | W13: 80 | X13: 100 | Y13: 99.604701 | Z13: 100 | AA13: 100 | AB13: =X13/100*E13 -> 30302.621 | AC13: =Y13/100*F13 -> 181097.01 | AD13: =Z13/100*G13 -> 66971.188 | AE13: =AA13/100*H13 -> 66971.188 | AF13: =SUM(AB13:AE13) -> 345342.01 | AG13: =AB13*J13/1000000 -> 7.0018371 | AH13: =AC13*K13/1000000 -> 33.475963 | AI13: =AD13*L13/1000000 -> 13.312705 | AJ13: =AE13*L13/1000000 -> 13.312705 | AK13: =SUM(AG13:AJ13) -> 67.10321
B14: LEBANON | C14: LBN | D14: LMIC | E14: 28431.624 | F14: 170589.74 | G14: 70952.551 | H14: 70952.551 | I14: 340926.47 | J14: 2185.1959 | K14: 1748.1567 | L14: 2027.4606 | M14: 58.49781 | N14: 101.68 | O14: 79.77729 | P14: 56.75473 | Q14: =VLOOKUP($C14,'Refugee GER'!$B$2:$G$73,4, FALSE) -> 0.27666067 | R14: =VLOOKUP($C14,'Refugee GER'!$B$2:$G$73,5, FALSE) -> 0.47681267 | S14: =VLOOKUP($C14,'Refugee GER'!$B$2:$G$73,6, FALSE) -> 0.11835085 | T14: 99 | U14: 92.6717 | V14: 81.047501 | W14: 81.047501 | X14: 100 | Y14: 99.604701 | Z14: 100 | AA14: 100 | AB14: =X14/100*E14 -> 28431.624 | AC14: =Y14/100*F14 -> 169915.41 | AD14: =Z14/100*G14 -> 70952.551 | AE14: =AA14/100*H14 -> 70952.551 | AF14: =SUM(AB14:AE14) -> 340252.13 | AG14: =AB14*J14/1000000 -> 62.128668 | AH14: =AC14*K14/1000000 -> 297.03876 | AI14: =AD14*L14/1000000 -> 143.8535 | AJ14: =AE14*L14/1000000 -> 143.8535 | AK14: =SUM(AG14:AJ14) -> 646.87443
B15: JORDAN | C15: JOR | D15: LMIC | E15: 21620.117 | F15: 129720.7 | G15: 56297.362 | H15: 56297.362 | I15: 263935.54 | J15: 1328.4335 | K15: 1062.7468 | L15: 1184.8369 | M15: 26.599661 | N15: 101.68 | O15: 74.32 | P15: 63.49 | Q15: =VLOOKUP($C15,'Refugee GER'!$B$2:$G$73,4, FALSE) -> 0.13814962 | R15: =VLOOKUP($C15,'Refugee GER'!$B$2:$G$73,5, FALSE) -> 0.66487346 | S15: =VLOOKUP($C15,'Refugee GER'!$B$2:$G$73,6, FALSE) -> 0.30242445 | T15: 55 | U15: 98 | V15: 94 | W15: 77 | X15: 100 | Y15: 99.604701 | Z15: 100 | AA15: 100 | AB15: =X15/100*E15 -> 21620.117 | AC15: =Y15/100*F15 -> 129207.92 | AD15: =Z15/100*G15 -> 56297.362 | AE15: =AA15/100*H15 -> 56297.362 | AF15: =SUM(AB15:AE15) -> 263422.76 | AG15: =AB15*J15/1000000 -> 28.720888 | AH15: =AC15*K15/1000000 -> 137.3153 | AI15: =AD15*L15/1000000 -> 66.70319 | AJ15: =AE15*L15/1000000 -> 66.70319 | AK15: =SUM(AG15:AJ15) -> 299.44257
... B75: PARAGUAY | C75: PRY | D75: UMIC | E75: 103.10302 | F75: 618.61815 | G75: 254.42494 | H75: 254.42494 | I75: 1230.571 | J75: 1309.3111 | K75: 1047.4488 | L75: 1185.4492 | M75: 51.091721 | N75: 93.23 | O75: 81.24 | P75: 82.8 | Q75: =VLOOKUP($C75,'Refugee GER'!$B$2:$G$73,4, FALSE) -> - | R75: =VLOOKUP($C75,'Refugee GER'!$B$2:$G$73,5, FALSE) -> - | S75: =VLOOKUP($C75,'Refugee GER'!$B$2:$G$73,6, FALSE) -> - | T75: 98.359447 | U75: 100 | V75: 97.4 | W75: 78.6 | X75: 100 | Y75: 99.604701 | Z75: 100 | AA75: 100 | AB75: =X75/100*E75 -> 103.10302 | AC75: =Y75/100*F75 -> 616.17276 | AD75: =Z75/100*G75 -> 254.42494 | AE75: =AA75/100*H75 -> 254.42494 | AF75: =SUM(AB75:AE75) -> 1228.1257 | AG75: =AB75*J75/1000000 -> 0.13499393 | AH75: =AC75*K75/1000000 -> 0.64540945 | AI75: =AD75*L75/1000000 -> 0.30160783 | AJ75: =AE75*L75/1000000 -> 0.30160783 | AK75: =SUM(AG75:AJ75) -> 1.383619
E76: =SUM(E4:E75) -> 764222.72 | F76: =SUM(F4:F75) -> 4585336.3 | G76: =SUM(G4:G75) -> 1897453.1 | H76: =SUM(H4:H75) -> 1897453.1 | I76: =SUM(I4:I75) -> 9144465.3 | AB76: =SUM(AB4:AB75) -> 764222.72 | AC76: =SUM(AC4:AC75) -> 4567210.5 | AD76: =SUM(AD4:AD75) -> 1897453.1 | AE76: =SUM(AE4:AE75) -> 1897453.1 | AF76: =SUM(AF4:AF75) -> 9126339.5 | AG76: =SUM(AG4:AG75) -> 843.27868 | AH76: =SUM(AH4:AH75) -> 4031.737 | AI76: =SUM(AI4:AI75) -> 2202.7803 | ... AK76: =SUM(AK4:AK75) -> 9280.5762

Sheet Refugee GER
A1: country | B1: code | C1: region | D1: incomegroup | E1: Pre-Primary_GER | F1: Primary_GER | G1: Secondary_GER | K1: Row Labels | L1: Average of Pre-Primary_GER | M1: Average of Primary_GER | N1: Average of Secondary_GER
A2: TüRKIYE | B2: TUR | C2: EUROPE & CENTRAL ASIA | D2: UPPER MIDDLE INCOME | E2: =VLOOKUP($B2,[3]Sheet1!$B$7:$K$246, 4, FALSE) -> 0.34337712 | F2: =VLOOKUP($B2,[3]Sheet1!$B$7:$K$246, 7, FALSE) -> 0.75128249 | G2: =VLOOKUP($B2,[3]Sheet1!$B$7:$K$246, 10, FALSE) -> 0.6396274 | K2: LOW INCOME | L2: 0.32660573 | M2: 0.5982858 | N2: 0.2658156
A3: IRAN (ISLAMIC REPUBLIC OF) | B3: IRN | C3: MIDDLE EAST & NORTH AFRICA | D3: LOWER MIDDLE INCOME | E3: =VLOOKUP($B3,[3]Sheet1!$B$7:$K$246, 4, FALSE) -> - | F3: =VLOOKUP($B3,[3]Sheet1!$B$7:$K$246, 7, FALSE) -> 0.88 | G3: =VLOOKUP($B3,[3]Sheet1!$B$7:$K$246, 10, FALSE) -> 0.73 | K3: LOWER MIDDLE INCOME | L3: 0.40243924 | M3: 0.65179214 | N3: 0.34847026
A4: UGANDA | B4: UGA | C4: SUB-SAHARAN AFRICA | D4: LOW INCOME | E4: =VLOOKUP($B4,[3]Sheet1!$B$7:$K$246, 4, FALSE) -> 0.39496804 | F4: =VLOOKUP($B4,[3]Sheet1!$B$7:$K$246, 7, FALSE) -> 0.86380566 | G4: =VLOOKUP($B4,[3]Sheet1!$B$7:$K$246, 10, FALSE) -> 0.095342737 | K4: UPPER MIDDLE INCOME | L4: 0.12203478 | M4: 0.59105034 | N4: 0.44932944
A5: PAKISTAN | B5: PAK | C5: SOUTH ASIA | D5: LOWER MIDDLE INCOME | E5: =VLOOKUP($B5,[3]Sheet1!$B$7:$K$246, 4, FALSE) -> 0.11217083 | F5: =VLOOKUP($B5,[3]Sheet1!$B$7:$K$246, 7, FALSE) -> 0.10205199 | G5: =VLOOKUP($B5,[3]Sheet1!$B$7:$K$246, 10, FALSE) -> 0.032401556 | K5: Grand Total | L5: 0.33560964 | M5: 0.61925338 | N5: 0.34313423
A6: COLOMBIA | B6: COL | C6: LATIN AMERICA & CARIBBEAN | D6: UPPER MIDDLE INCOME | E6: =VLOOKUP($B6,[3]Sheet1!$B$7:$K$246, 4, FALSE) -> - | F6: =VLOOKUP($B6,[3]Sheet1!$B$7:$K$246, 7, FALSE) -> 0.53016469 | G6: =VLOOKUP($B6,[3]Sheet1!$B$7:$K$246, 10, FALSE) -> 0.22220363
A7: PERU | B7: PER | C7: LATIN AMERICA & CARIBBEAN | D7: UPPER MIDDLE INCOME | E7: =VLOOKUP($B7,[3]Sheet1!$B$7:$K$246, 4, FALSE) -> - | F7: =VLOOKUP($B7,[3]Sheet1!$B$7:$K$246, 7, FALSE) -> 0.42018735 | G7: =VLOOKUP($B7,[3]Sheet1!$B$7:$K$246, 10, FALSE) -> 0.30591971
A8: SUDAN | B8: SDN | C8: SUB-SAHARAN AFRICA | D8: LOW INCOME | E8: =VLOOKUP($B8,[3]Sheet1!$B$7:$K$246, 4, FALSE) -> 0.03274802 | F8: =VLOOKUP($B8,[3]Sheet1!$B$7:$K$246, 7, FALSE) -> 0.30468948 | G8: =VLOOKUP($B8,[3]Sheet1!$B$7:$K$246, 10, FALSE) -> 0.068999705
A9: RUSSIAN FEDERATION | B9: RUS | C9: EUROPE & CENTRAL ASIA | D9: UPPER MIDDLE INCOME | E9: - | F9: - | G9: -
A10: ETHIOPIA | B10: ETH | C10: SUB-SAHARAN AFRICA | D10: LOW INCOME | E10: =VLOOKUP($B10,[3]Sheet1!$B$7:$K$246, 4, FALSE) -> 0.40753682 | F10: =VLOOKUP($B10,[3]Sheet1!$B$7:$K$246, 7, FALSE) -> 0.53575945 | G10: =VLOOKUP($B10,[3]Sheet1!$B$7:$K$246, 10, FALSE) -> 0.19805083 | L10: Pre-primary | M10: Primary | N10: Secondary
A11: BANGLADESH | B11: BGD | C11: SOUTH ASIA | D11: LOWER MIDDLE INCOME | E11: =VLOOKUP($B11,[3]Sheet1!$B$7:$K$246, 4, FALSE) -> 0.45280469 | F11: =VLOOKUP($B11,[3]Sheet1!$B$7:$K$246, 7, FALSE) -> 0.28483199 | G11: =VLOOKUP($B11,[3]Sheet1!$B$7:$K$246, 10, FALSE) -> 0.0059634212 | K11: LIC | L11: =GETPIVOTDATA("Average of Pre-Primary_GER",$K$1,"incomegroup","LOW INCOME") -> 0.32660573 | M11: =GETPIVOTDATA("Average of Primary_GER",$K$1,"incomegroup","LOW INCOME") -> 0.5982858 | N11: =GETPIVOTDATA("Average of Secondary_GER",$K$1,"incomegroup","LOW INCOME") -> 0.2658156
A12: LEBANON | B12: LBN | C12: MIDDLE EAST & NORTH AFRICA | D12: LOWER MIDDLE INCOME | E12: =VLOOKUP($B12,[3]Sheet1!$B$7:$K$246, 4, FALSE) -> 0.27666067 | F12: =VLOOKUP($B12,[3]Sheet1!$B$7:$K$246, 7, FALSE) -> 0.47681267 | G12: =VLOOKUP($B12,[3]Sheet1!$B$7:$K$246, 10, FALSE) -> 0.11835085 | K12: LMIC | L12: =GETPIVOTDATA("Average of Pre-Primary_GER",$K$1,"incomegroup","LOWER MIDDLE INCOME") -> 0.40243924 | M12: =GETPIVOTDATA("Average of Primary_GER",$K$1,"incomegroup","LOWER MIDDLE INCOME") -> 0.65179214 | N12: =GETPIVOTDATA("Average of Secondary_GER",$K$1,"incomegroup","LOWER MIDDLE INCOME") -> 0.34847026
A13: JORDAN | B13: JOR | C13: MIDDLE EAST & NORTH AFRICA | D13: LOWER MIDDLE INCOME | E13: =VLOOKUP($B13,[3]Sheet1!$B$7:$K$246, 4, FALSE) -> 0.13814962 | F13: =VLOOKUP($B13,[3]Sheet1!$B$7:$K$246, 7, FALSE) -> 0.66487346 | G13: =VLOOKUP($B13,[3]Sheet1!$B$7:$K$246, 10, FALSE) -> 0.30242445 | K13: UMIC | L13: =GETPIVOTDATA("Average of Pre-Primary_GER",$K$1,"incomegroup","UPPER MIDDLE INCOME") -> 0.12203478 | M13: =GETPIVOTDATA("Average of Primary_GER",$K$1,"incomegroup","UPPER MIDDLE INCOME") -> 0.59105034 | N13: =GETPIVOTDATA("Average of Secondary_GER",$K$1,"incomegroup","UPPER MIDDLE INCOME") -> 0.44932944
A14: DEMOCRATIC REPUBLIC OF THE CONGO | B14: COD | C14: SUB-SAHARAN AFRICA | D14: LOW INCOME | E14: =VLOOKUP($B14,[3]Sheet1!$B$7:$K$246, 4, FALSE) -> - | F14: =VLOOKUP($B14,[3]Sheet1!$B$7:$K$246, 7, FALSE) -> 0.50990294 | G14: =VLOOKUP($B14,[3]Sheet1!$B$7:$K$246, 10, FALSE) -> 0.30551614
A15: KENYA | B15: KEN | C15: SUB-SAHARAN AFRICA | D15: LOWER MIDDLE INCOME | E15: =VLOOKUP($B15,[3]Sheet1!$B$7:$K$246, 4, FALSE) -> 0.72231344 | F15: =VLOOKUP($B15,[3]Sheet1!$B$7:$K$246, 7, FALSE) -> 0.71407831 | G15: =VLOOKUP($B15,[3]Sheet1!$B$7:$K$246, 10, FALSE) -> 0.46562677
A16: CHAD | B16: TCD | C16: SUB-SAHARAN AFRICA | D16: LOW INCOME | E16: =VLOOKUP($B16,[3]Sheet1!$B$7:$K$246, 4, FALSE) -> 0.12686793 | F16: =VLOOKUP($B16,[3]Sheet1!$B$7:$K$246, 7, FALSE) -> 0.71194018 | G16: =VLOOKUP($B16,[3]Sheet1!$B$7:$K$246, 10, FALSE) -> 0.23166938
A17: CAMEROON | B17: CMR | C17: SUB-SAHARAN AFRICA | D17: LOWER MIDDLE INCOME | E17: =VLOOKUP($B17,[3]Sheet1!$B$7:$K$246, 4, FALSE) -> 0.056213757 | F17: =VLOOKUP($B17,[3]Sheet1!$B$7:$K$246, 7, FALSE) -> 0.46779187 | G17: =VLOOKUP($B17,[3]Sheet1!$B$7:$K$246, 10, FALSE) -> 0.049578693
A18: BRAZIL | B18: BRA | C18: LATIN AMERICA & CARIBBEAN | D18: UPPER MIDDLE INCOME | E18: =VLOOKUP($B18,[3]Sheet1!$B$7:$K$246, 4, FALSE) -> - | F18: =VLOOKUP($B18,[3]Sheet1!$B$7:$K$246, 7, FALSE) -> 0.90436154 | G18: =VLOOKUP($B18,[3]Sheet1!$B$7:$K$246, 10, FALSE) -> 0.55994468
A19: NIGER | B19: NER | C19: SUB-SAHARAN AFRICA | D19: LOW INCOME | E19: =VLOOKUP($B19,[3]Sheet1!$B$7:$K$246, 4, FALSE) -> 0.26386109 | F19: =VLOOKUP($B19,[3]Sheet1!$B$7:$K$246, 7, FALSE) -> 0.35635299 | G19: =VLOOKUP($B19,[3]Sheet1!$B$7:$K$246, 10, FALSE) -> 0.014742295
A20: SOUTH SUDAN | B20: SSD | C20: SUB-SAHARAN AFRICA | D20: LOW INCOME | E20: =VLOOKUP($B20,[3]Sheet1!$B$7:$K$246, 4, FALSE) -> 0.44496344 | F20: =VLOOKUP($B20,[3]Sheet1!$B$7:$K$246, 7, FALSE) -> 0.66453104 | G20: =VLOOKUP($B20,[3]Sheet1!$B$7:$K$246, 10, FALSE) -> 0.43786004
A21: IRAQ | B21: IRQ | C21: MIDDLE EAST & NORTH AFRICA | D21: UPPER MIDDLE INCOME | E21: =VLOOKUP($B21,[3]Sheet1!$B$7:$K$246, 4, FALSE) -> 0 | F21: =VLOOKUP($B21,[3]Sheet1!$B$7:$K$246, 7, FALSE) -> 0.67414889 | G21: =VLOOKUP($B21,[3]Sheet1!$B$7:$K$246, 10, FALSE) -> 0.32493285
A22: UNITED REPUBLIC OF TANZANIA | B22: TZA | C22: SUB-SAHARAN AFRICA | D22: LOWER MIDDLE INCOME | E22: =VLOOKUP($B22,[3]Sheet1!$B$7:$K$246, 4, FALSE) -> 0.70453853 | F22: =VLOOKUP($B22,[3]Sheet1!$B$7:$K$246, 7, FALSE) -> 1.4297182 | G22: =VLOOKUP($B22,[3]Sheet1!$B$7:$K$246, 10, FALSE) -> 0.39049081
A23: EGYPT | B23: EGY | C23: MIDDLE EAST & NORTH AFRICA | D23: LOWER MIDDLE INCOME | E23: =VLOOKUP($B23,[3]Sheet1!$B$7:$K$246, 4, FALSE) -> 0.66649572 | F23: =VLOOKUP($B23,[3]Sheet1!$B$7:$K$246, 7, FALSE) -> 0.84998352 | G23: =VLOOKUP($B23,[3]Sheet1!$B$7:$K$246, 10, FALSE) -> 0.78997873
A24: INDIA | B24: IND | C24: SOUTH ASIA | D24: LOWER MIDDLE INCOME | E24: =VLOOKUP($B24,[3]Sheet1!$B$7:$K$246, 4, FALSE) -> - | F24: =VLOOKUP($B24,[3]Sheet1!$B$7:$K$246, 7, FALSE) -> 0.60002537 | G24: =VLOOKUP($B24,[3]Sheet1!$B$7:$K$246, 10, FALSE) -> 0.31022624
A25: MEXICO | B25: MEX | C25: LATIN AMERICA & CARIBBEAN | D25: UPPER MIDDLE INCOME | E25: =VLOOKUP($B25,[3]Sheet1!$B$7:$K$246, 4, FALSE) -> - | F25: =VLOOKUP($B25,[3]Sheet1!$B$7:$K$246, 7, FALSE) -> - | G25: =VLOOKUP($B25,[3]Sheet1!$B$7:$K$246, 10, FALSE) -> -
A26: ECUADOR | B26: ECU | C26: LATIN AMERICA & CARIBBEAN | D26: UPPER MIDDLE INCOME | E26: =VLOOKUP($B26,[3]Sheet1!$B$7:$K$246, 4, FALSE) -> - | F26: =VLOOKUP($B26,[3]Sheet1!$B$7:$K$246, 7, FALSE) -> 0.83 | G26: =VLOOKUP($B26,[3]Sheet1!$B$7:$K$246, 10, FALSE) -> 0.55
A27: BULGARIA | B27: BGR | C27: EUROPE & CENTRAL ASIA | D27: UPPER MIDDLE INCOME | E27: - | F27: - | G27: -
A28: MAURITANIA | B28: MRT | C28: SUB-SAHARAN AFRICA | D28: LOWER MIDDLE INCOME | E28: =VLOOKUP($B28,[3]Sheet1!$B$7:$K$246, 4, FALSE) -> 0.091142597 | F28: =VLOOKUP($B28,[3]Sheet1!$B$7:$K$246, 7, FALSE) -> 0.29891035 | G28: =VLOOKUP($B28,[3]Sheet1!$B$7:$K$246, 10, FALSE) -> 0.064118205
A29: RWANDA | B29: RWA | C29: SUB-SAHARAN AFRICA | D29: LOW INCOME | E29: =VLOOKUP($B29,[3]Sheet1!$B$7:$K$246, 4, FALSE) -> 0.71841319 | F29: =VLOOKUP($B29,[3]Sheet1!$B$7:$K$246, 7, FALSE) -> 1.2455106 | G29: =VLOOKUP($B29,[3]Sheet1!$B$7:$K$246, 10, FALSE) -> 0.72504255
A30: MALAYSIA | B30: MYS | C30: EAST ASIA & PACIFIC | D30: UPPER MIDDLE INCOME | E30: =VLOOKUP($B30,[3]Sheet1!$B$7:$K$246, 4, FALSE) -> 0.21672091 | F30: =VLOOKUP($B30,[3]Sheet1!$B$7:$K$246, 7, FALSE) -> 0.42857143 | G30: =VLOOKUP($B30,[3]Sheet1!$B$7:$K$246, 10, FALSE) -> 0.30498392
A31: DOMINICAN REPUBLIC | B31: DOM | C31: LATIN AMERICA & CARIBBEAN | D31: UPPER MIDDLE INCOME | E31: =VLOOKUP($B31,[3]Sheet1!$B$7:$K$246, 4, FALSE) -> - | F31: =VLOOKUP($B31,[3]Sheet1!$B$7:$K$246, 7, FALSE) -> - | G31: =VLOOKUP($B31,[3]Sheet1!$B$7:$K$246, 10, FALSE) -> -
A32: NIGERIA | B32: NGA | C32: SUB-SAHARAN AFRICA | D32: LOWER MIDDLE INCOME | E32: =VLOOKUP($B32,[3]Sheet1!$B$7:$K$246, 4, FALSE) -> 0.63998577 | F32: =VLOOKUP($B32,[3]Sheet1!$B$7:$K$246, 7, FALSE) -> 0.44056481 | G32: =VLOOKUP($B32,[3]Sheet1!$B$7:$K$246, 10, FALSE) -> 0.32836202
A33: BURUNDI | B33: BDI | C33: SUB-SAHARAN AFRICA | D33: LOW INCOME | E33: =VLOOKUP($B33,[3]Sheet1!$B$7:$K$246, 4, FALSE) -> 0.53651301 | F33: =VLOOKUP($B33,[3]Sheet1!$B$7:$K$246, 7, FALSE) -> 0.77937564 | G33: =VLOOKUP($B33,[3]Sheet1!$B$7:$K$246, 10, FALSE) -> 0.59117067
A34: REPUBLIC OF MOLDOVA | B34: MDA | C34: EUROPE & CENTRAL ASIA | D34: UPPER MIDDLE INCOME | E34: - | F34: - | G34: -
A35: ALGERIA | B35: DZA | C35: MIDDLE EAST & NORTH AFRICA | D35: LOWER MIDDLE INCOME | E35: =VLOOKUP($B35,[3]Sheet1!$B$7:$K$246, 4, FALSE) -> 0.073513514 | F35: =VLOOKUP($B35,[3]Sheet1!$B$7:$K$246, 7, FALSE) -> 0.35771812 | G35: =VLOOKUP($B35,[3]Sheet1!$B$7:$K$246, 10, FALSE) -> 0.20813876
A36: THAILAND | B36: THA | C36: EAST ASIA & PACIFIC | D36: UPPER MIDDLE INCOME | E36: =VLOOKUP($B36,[3]Sheet1!$B$7:$K$246, 4, FALSE) -> - | F36: =VLOOKUP($B36,[3]Sheet1!$B$7:$K$246, 7, FALSE) -> 0.64058873 | G36: =VLOOKUP($B36,[3]Sheet1!$B$7:$K$246, 10, FALSE) -> 0.87290828
A37: MALI | B37: MLI | C37: SUB-SAHARAN AFRICA | D37: LOW INCOME | E37: =VLOOKUP($B37,[3]Sheet1!$B$7:$K$246, 4, FALSE) -> 0.38417832 | F37: =VLOOKUP($B37,[3]Sheet1!$B$7:$K$246, 7, FALSE) -> 0.5725134 | G37: =VLOOKUP($B37,[3]Sheet1!$B$7:$K$246, 10, FALSE) -> 0.13556055
A38: ANGOLA | B38: AGO | C38: SUB-SAHARAN AFRICA | D38: LOWER MIDDLE INCOME | E38: =VLOOKUP($B38,[3]Sheet1!$B$7:$K$246, 4, FALSE) -> 0.7199341 | F38: =VLOOKUP($B38,[3]Sheet1!$B$7:$K$246, 7, FALSE) -> 1.0777706 | G38: =VLOOKUP($B38,[3]Sheet1!$B$7:$K$246, 10, FALSE) -> 0.28743169
A39: ZAMBIA | B39: ZMB | C39: SUB-SAHARAN AFRICA | D39: LOWER MIDDLE INCOME | E39: =VLOOKUP($B39,[3]Sheet1!$B$7:$K$246, 4, FALSE) -> 0.18469969 | F39: =VLOOKUP($B39,[3]Sheet1!$B$7:$K$246, 7, FALSE) -> 0.76825021 | G39: =VLOOKUP($B39,[3]Sheet1!$B$7:$K$246, 10, FALSE) -> 0.29741251
A40: SOUTH AFRICA | B40: ZAF | C40: SUB-SAHARAN AFRICA | D40: UPPER MIDDLE INCOME | E40: =VLOOKUP($B40,[3]Sheet1!$B$7:$K$246, 4, FALSE) -> - | F40: =VLOOKUP($B40,[3]Sheet1!$B$7:$K$246, 7, FALSE) -> 0.95694975 | G40: =VLOOKUP($B40,[3]Sheet1!$B$7:$K$246, 10, FALSE) -> 0.89670438
...
